Workbook

Sheet README
B1: High-Mileage Vehicle Turnover Planner
B2: Built for a ~55,000 mi/yr driver in Hamilton County, Indiana
B4: HOW TO USE
B5: 1. Start on Inputs | C5: Every assumption in this workbook lives there. Change a number and the whole model recalculates. Nothing downstream is hardcoded.
B6: 2. Replace the purchase prices | C6: The prices on the Models tab are placeholder estimates, NOT quotes. Pull real local listings at your target odometer and overwrite them. This is the single biggest driver of the answer.
B7: 3. Read Models | C7: Head-to-head cost per mile across 70+ candidates, decomposed into depreciation, fuel, tires, maintenance, repair reserve, insurance, taxes, and cost of capital. Filter row 6 by Tier, Category, Fuel, or GVWR. Tier 1 is green (buy with confidence), Tier 2 amber (one caveat to manage), Tier 3 red (poor 180k-mile bet). Column AE ranks every model by cost per mile.
B8: 4. Read Strategies | C8: Compares buy-point / sell-point strategies (buy at 40k and sell at 150k vs. 180k, buy older, buy new, lease). Answers 'when do I turn over' rather than 'what do I buy'.
B9: 5. Run Tax | C9: Five ownership structures side by side, including Section 179 / bonus depreciation with the recapture cost modeled. Set employment type on Inputs first — it changes everything.
B10: 6. Log to Tracker | C10: Once a vehicle is in service, log every fuel stop, tire set, and repair. The summary block computes actual cost per mile so you can check the model against reality.
B12: COLOR LEGEND
B13: Blue text | C13: An input you can and should edit. Scenario levers and hardcoded assumptions.
B14: Black text | C14: A formula. Don't overwrite these — they'll stop recalculating.
B15: Green text | C15: A link pulling a value from another tab.
B16: Yellow fill | C16: A key assumption worth reviewing before you trust the output.
B18: READ THIS BEFORE TRUSTING THE TAX TAB
C19: • W-2 employees cannot deduct business mileage. The Tax Cuts and Jobs Act suspended unreimbursed employee business expenses, and the One Big Beautiful Bill Act (signed 7/4/2025) made that suspension permanent by amending IRC 67(g) to remove the sunset. IRS Publication 463 confirms it. If the driver is a W-2 employee, set Employment type to 'W-2' on Inputs and the model will correctly show a zero deduction benefit.
C20: • Only self-employment / Schedule C / business-entity miles produce a deduction. Set Employment type to 'Self-employed' only if that is actually the case.
C21: • Section 179 and bonus depreciation are a TIMING benefit at this turnover cadence, not a savings. Vehicles are Section 1245 property, so depreciation comes back as ORDINARY income on sale. Selling every ~30 months means recapture arrives fast. The Tax tab models this explicitly — look at the net, not the year-one deduction.
C22: • Claiming Section 179 or bonus on a vehicle permanently bars the standard mileage rate on that vehicle. There is no switching back.
C23: • None of this is tax advice. Confirm every figure with a CPA before filing. Indiana's treatment of business vehicle deductions may not track federal.
B25: MODEL LIMITATIONS
C26: • The depreciation curve comes from pooled asking-price cross-sections (~327,000 US listings), not the same VIN tracked over time. Different cars sit in each odometer band. Treat the coefficients as directional.
C27: • Purchase prices on the Models tab are estimates for illustration. Replace them with real listings.
C28: • Repair reserve rates are judgment calls calibrated to published major-repair incidence data. They are the softest numbers in the workbook — flex them on the Inputs tab to see how much the answer moves.
C29: • The finance cost uses an average-outstanding-balance approximation rather than a full amortization schedule. It is accurate to within a few hundred dollars over a 30-month cycle, not to the penny.
C30: • Insurance and Indiana excise figures are representative for Hamilton County, not a quote.

Sheet Inputs
B1: Inputs and Assumptions
B2: Blue cells are yours to change. Everything else in the workbook reads from here.
B4: DRIVING PATTERN & CYCLE
B5: Annual miles driven | C5: 55000 | D5: Stated: 50,000-60,000 per year. 55,000 is the midpoint.
B6: Buy odometer (miles) | C6: 40000 | D6: Odometer at purchase. The most important lever in the workbook.
B7: Sell odometer (miles) | C7: 180000 | D7: Odometer at disposal. Stated preference: 150,000-180,000.
B8: Miles per ownership cycle | C8: =C7-C6 -> 140000
B9: Years per cycle | C9: =IFERROR(C8/C5,0) -> 2.5454545
B10: Months per cycle | C10: =C9*12 -> 30.545455
B12: OPERATING COSTS
B13: Gasoline ($/gal) | C13: 3.55 | D13: Indiana average, AAA, early Aug 2026. National avg was $4.06-4.11.
B14: Diesel ($/gal) | C14: 5.35 | D14: Indiana average, AAA, early Aug 2026.
B15: Tire set - crossover ($ installed) | C15: 900 | D15: Range $700-$1,200 installed for crossover/SUV sizes.
B16: Tire set - truck ($ installed) | C16: 1300 | D16: Range $900-$1,500 for half-ton LT tires.
B17: Tire life (miles per set) | C17: 55000 | D17: Consumer Reports treadwear testing: 70,000-100,000 for premium touring. Derated for load and highway speed.
B18: Scheduled maintenance ($/mile) | C18: 0.08 | D18: Oil, brakes, plugs, fluids, transfer case. AAA's SUV line is $0.108-0.118/mi.
B19: Insurance ($/year) | C19: 1600 | D19: Indiana full coverage estimates range $1,009-$1,856 depending on source.
B20: Registration + excise + wheel tax ($/yr) | C20: 450 | D20: Hamilton County: $21.35 BMV base + $15 wheel tax + excise surtax. Excise declines as the vehicle ages.
B22: REPAIR RESERVE (the softest numbers here)
B23: Under 100,000 miles ($/mile) | C23: 0.03 | D23: Unscheduled repairs only. Scheduled work is on row 18.
B24: 100,000-150,000 miles ($/mile) | C24: 0.06 | D24: Failure incidence climbs sharply past 100k.
B25: Over 150,000 miles ($/mile) | C25: 0.1 | D25: Roughly 2/3 of vehicles over 100k hit a major repair averaging $3,847/yr per CoverageX (a warranty seller - read as a ceiling).
B26: Cycle miles in the <100k band | C26: =MAX(0,MIN(C7,100000)-C6) -> 60000
B27: Cycle miles in the 100k-150k band | C27: =MAX(0,MIN(C7,150000)-MAX(C6,100000)) -> 50000
B28: Cycle miles in the >150k band | C28: =MAX(0,C7-MAX(C6,150000)) -> 30000
B29: Blended repair reserve ($/mile) | C29: =IFERROR((C26*C23+C27*C24+C28*C25)/C8,0) -> 0.055714286 | D29: Weighted by how many cycle miles fall in each band.
B31: CAPITAL & FINANCING
B32: Financing mode | C32: Cash | D32: Pick one. Both are computed on the Models tab; this selects which flows into the total.
B33: Cash opportunity cost rate | C33: 0.045 | D33: Return foregone on capital tied up in the vehicle.
B34: Loan APR | C34: 0.065 | D34: Used-vehicle rate. Adjust to a real quote.
B35: Down payment % | C35: 0.2
B36: Average outstanding balance factor | C36: 0.55 | D36: Approximation. A loan held about half its term averages ~55% of principal outstanding. Avoids a full amortization schedule.
B38: TAX
B39: Employment type | C39: Self-employed | D39: W-2 employees get NO mileage deduction post-OBBBA (IRC 67(g), IRS Pub 463). Set this honestly - it zeroes out the tax benefit.
B40: Business use % | C40: 0.9 | D40: Must exceed 50% to claim Section 179 or bonus. Requires a contemporaneous mileage log.
B41: IRS standard mileage rate ($/mi) | C41: 0.74 | D41: 2026: 72.5c Jan-Jun (Notice 2026-10), raised to 76c Jul-Dec (Announcement 2026-11). 74c is the blended rate.
B42: Marginal federal income tax rate | C42: 0.24
B43: Self-employment tax effective rate | C43: 0.1413 | D43: 15.3% on 92.35% of net SE income, before the employer-half deduction.
B44: Indiana state income tax rate | C44: 0.0305
B45: Combined deduction benefit rate | C45: =IF(C39="Self-employed",C42+C43+C44,0) -> 0.4118 | D45: Zero for W-2 because the deduction does not exist. This is the whole ballgame.
...

Sheet Depreciation
B1: Depreciation Engine
B2: Value retention as a function of odometer, converted to an index so it scales to any purchase price.
B4: Odometer | C4: Median listing price | D4: Retention index | E4: $ lost per 1,000 mi in band
B5: 0 | C5: 35000 | D5: =C5/$C$5 -> 1
B6: 10000 | C6: 33900 | D6: =C6/$C$5 -> 0.96857143 | E6: =IFERROR((C5-C6)/((B6-B5)/1000),0) -> 110
B7: 25000 | C7: 33480 | D7: =C7/$C$5 -> 0.95657143 | E7: =IFERROR((C6-C7)/((B7-B6)/1000),0) -> 28
B8: 50000 | C8: 26000 | D8: =C8/$C$5 -> 0.74285714 | E8: =IFERROR((C7-C8)/((B8-B7)/1000),0) -> 299.2
B9: 75000 | C9: 18995 | D9: =C9/$C$5 -> 0.54271429 | E9: =IFERROR((C8-C9)/((B9-B8)/1000),0) -> 280.2
B10: 100000 | C10: 14500 | D10: =C10/$C$5 -> 0.41428571 | E10: =IFERROR((C9-C10)/((B10-B9)/1000),0) -> 179.8
B11: 125000 | C11: 10950 | D11: =C11/$C$5 -> 0.31285714 | E11: =IFERROR((C10-C11)/((B11-B10)/1000),0) -> 142
B12: 150000 | C12: 8900 | D12: =C12/$C$5 -> 0.25428571 | E12: =IFERROR((C11-C12)/((B12-B11)/1000),0) -> 82
B13: 200000 | C13: 6450 | D13: =C13/$C$5 -> 0.18428571 | E13: =IFERROR((C12-C13)/((B13-B12)/1000),0) -> 49
B14: 250000 | C14: 4500 | D14: =C14/$C$5 -> 0.12857143 | E14: =IFERROR((C13-C14)/((B14-B13)/1000),0) -> 39
B15: Source: pooled analysis of ~327,000 US used listings (ForCar, Aug 2026). The $0 / $35,000 anchor is extrapolated to give the index a clean base. Asking-price cross-sections, not tracked VINs.
B18: APPLIED TO YOUR CYCLE
B19: Buy odometer | C19: =Inputs!$C$6 -> 40000 | D19: Pulled from Inputs.
B20: Sell odometer | C20: =Inputs!$C$7 -> 180000 | D20: Pulled from Inputs.
B21: Retention index at buy | C21: =IFERROR(INDEX($D$5:$D$14,MATCH($C$19,$B$5:$B$14,1))+($C$19-INDEX($B$5:$B$14,MATCH($C$19,$B$5:$B$14,1)))/(INDEX($B$5:$B$14,MATCH($C$19,$B$5:$B$14,1)+1)-INDEX($B$5:$B$14,MATCH($C$19,$B$5:$B$14,1)))*(INDEX($D$5:$D$14,MATCH($C$19,$B$5:$B$14,1)+1)-INDEX($D$5:$D$14,MATCH($C$19,$B$5:$B$14,1))),INDEX($D$5:$D$14,MATCH($C$19,$B$5:$B$14,1))) -> 0.82834286 | D21: Interpolated between the anchors above.
B22: Retention index at sell | C22: =IFERROR(INDEX($D$5:$D$14,MATCH($C$20,$B$5:$B$14,1))+($C$20-INDEX($B$5:$B$14,MATCH($C$20,$B$5:$B$14,1)))/(INDEX($B$5:$B$14,MATCH($C$20,$B$5:$B$14,1)+1)-INDEX($B$5:$B$14,MATCH($C$20,$B$5:$B$14,1)))*(INDEX($D$5:$D$14,MATCH($C$20,$B$5:$B$14,1)+1)-INDEX($D$5:$D$14,MATCH($C$20,$B$5:$B$14,1))),INDEX($D$5:$D$14,MATCH($C$20,$B$5:$B$14,1))) -> 0.21228571 | D22: Interpolated between the anchors above.
B23: Retention ratio (sell / buy) | C23: =IFERROR(C22/C21,0) -> 0.25627759 | D23: The fraction of the purchase price a market-average vehicle retains across your cycle. The Models tab multiplies this by a per-model resale strength factor.
B25: SCRATCH CALCULATOR
B26: Any odometer | C26: 120000
B27: Retention index there | C27: =IFERROR(INDEX($D$5:$D$14,MATCH($C$26,$B$5:$B$14,1))+($C$26-INDEX($B$5:$B$14,MATCH($C$26,$B$5:$B$14,1)))/(INDEX($B$5:$B$14,MATCH($C$26,$B$5:$B$14,1)+1)-INDEX($B$5:$B$14,MATCH($C$26,$B$5:$B$14,1)))*(INDEX($D$5:$D$14,MATCH($C$26,$B$5:$B$14,1)+1)-INDEX($D$5:$D$14,MATCH($C$26,$B$5:$B$14,1))),INDEX($D$5:$D$14,MATCH($C$26,$B$5:$B$14,1))) -> 0.33314286
B28: Est. value of a $35,000-when-new vehicle | C28: =C27*$C$5 -> 11660
B30: HOLD-PERIOD LOOKUP
B31: Hold period | C31: Sell odometer | D31: Retention index | E31: Retention ratio vs buy
B32: 1 year | C32: =Inputs!$C$6+1*Inputs!$C$5 -> 95000 | D32: =IFERROR(INDEX($D$5:$D$14,MATCH($C$32,$B$5:$B$14,1))+($C$32-INDEX($B$5:$B$14,MATCH($C$32,$B$5:$B$14,1)))/(INDEX($B$5:$B$14,MATCH($C$32,$B$5:$B$14,1)+1)-INDEX($B$5:$B$14,MATCH($C$32,$B$5:$B$14,1)))*(INDEX($D$5:$D$14,MATCH($C$32,$B$5:$B$14,1)+1)-INDEX($D$5:$D$14,MATCH($C$32,$B$5:$B$14,1))),INDEX($D$5:$D$14,MATCH($C$32,$B$5:$B$14,1))) -> 0.43997143 | E32: =IFERROR(D32/$C$21,0) -> 0.53114652
B33: 2 years | C33: =Inputs!$C$6+2*Inputs!$C$5 -> 150000 | D33: =IFERROR(INDEX($D$5:$D$14,MATCH($C$33,$B$5:$B$14,1))+($C$33-INDEX($B$5:$B$14,MATCH($C$33,$B$5:$B$14,1)))/(INDEX($B$5:$B$14,MATCH($C$33,$B$5:$B$14,1)+1)-INDEX($B$5:$B$14,MATCH($C$33,$B$5:$B$14,1)))*(INDEX($D$5:$D$14,MATCH($C$33,$B$5:$B$14,1)+1)-INDEX($D$5:$D$14,MATCH($C$33,$B$5:$B$14,1))),INDEX($D$5:$D$14,MATCH($C$33,$B$5:$B$14,1))) -> 0.25428571 | E33: =IFERROR(D33/$C$21,0) -> 0.30698124
B34: 2.5 years | C34: =Inputs!$C$6+2.5*Inputs!$C$5 -> 177500 | D34: =IFERROR(INDEX($D$5:$D$14,MATCH($C$34,$B$5:$B$14,1))+($C$34-INDEX($B$5:$B$14,MATCH($C$34,$B$5:$B$14,1)))/(INDEX($B$5:$B$14,MATCH($C$34,$B$5:$B$14,1)+1)-INDEX($B$5:$B$14,MATCH($C$34,$B$5:$B$14,1)))*(INDEX($D$5:$D$14,MATCH($C$34,$B$5:$B$14,1)+1)-INDEX($D$5:$D$14,MATCH($C$34,$B$5:$B$14,1))),INDEX($D$5:$D$14,MATCH($C$34,$B$5:$B$14,1))) -> 0.21578571 | E34: =IFERROR(D34/$C$21,0) -> 0.2605029
B35: 3 years | C35: =Inputs!$C$6+3*Inputs!$C$5 -> 205000 | D35: =IFERROR(INDEX($D$5:$D$14,MATCH($C$35,$B$5:$B$14,1))+($C$35-INDEX($B$5:$B$14,MATCH($C$35,$B$5:$B$14,1)))/(INDEX($B$5:$B$14,MATCH($C$35,$B$5:$B$14,1)+1)-INDEX($B$5:$B$14,MATCH($C$35,$B$5:$B$14,1)))*(INDEX($D$5:$D$14,MATCH($C$35,$B$5:$B$14,1)+1)-INDEX($D$5:$D$14,MATCH($C$35,$B$5:$B$14,1))),INDEX($D$5:$D$14,MATCH($C$35,$B$5:$B$14,1))) -> 0.17871429 | E35: =IFERROR(D35/$C$21,0) -> 0.21574917
B36: 4 years | C36: =Inputs!$C$6+4*Inputs!$C$5 -> 260000 | D36: =IFERROR(INDEX($D$5:$D$14,MATCH($C$36,$B$5:$B$14,1))+($C$36-INDEX($B$5:$B$14,MATCH($C$36,$B$5:$B$14,1)))/(INDEX($B$5:$B$14,MATCH($C$36,$B$5:$B$14,1)+1)-INDEX($B$5:$B$14,MATCH($C$36,$B$5:$B$14,1)))*(INDEX($D$5:$D$14,MATCH($C$36,$B$5:$B$14,1)+1)-INDEX($D$5:$D$14,MATCH($C$36,$B$5:$B$14,1))),INDEX($D$5:$D$14,MATCH($C$36,$B$5:$B$14,1))) -> 0.12857143 | E36: =IFERROR(D36/$C$21,0) -> 0.15521523
B37: Ratio = what fraction of the purchase price a market-average vehicle retains over that hold. The Models and HoldPeriod tabs multiply this by each model's resale-strength factor.

Sheet Models
A1: Model Comparison — Cost Per Mile
A2: Purchase prices in column G are PLACEHOLDER ESTIMATES, not quotes. Replace them with real local listings at your buy odometer before deciding anything.
A3: Use the filter arrows on row 6 to narrow by category, tier, fuel, or GVWR eligibility. Column AE ranks every model by total cost per mile (1 = cheapest).
A6: Model | B6: Category | C6: Tier | D6: 5-yr deprec. | E6: Deprec. source | F6: Resale mult. | G6: Purchase price | H6: Hwy MPG | I6: Fuel | J6: Tire class | K6: >6,000 lb GVWR | L6: 250k odds | M6: Odds study yr | N6: Known risk / red flag | O6: Est. resale | P6: Deprec. $ | Q6: Deprec. $/mi | R6: Fuel $/mi | S6: Tires $/mi | T6: Sched. maint $/mi | U6: Repair res. $/mi | V6: Insurance $/mi | W6: Reg/tax $/mi | X6: Sales tax $/mi | Y6: Capital $/mi (cash) | Z6: Capital $/mi (finance) | AA6: Capital $/mi (selected) | AB6: TOTAL $/mi | AC6: Cost per cycle | AD6: Cost per year | AE6: Rank | AF6: Reliability score | AG6: Comfort score | AH6: Cabin dB @55mph | AI6: dB source | AJ6: Resale @ 2 yr | AK6: Deprec. $/mi @ 2 yr
A7: Chevrolet Tahoe | B7: Full-size BOF SUV | C7: Tier 1 | D7: 0.453 | E7: iSeeCars 2026 | F7: =(1-D7)/(1-Inputs!$C$54) -> 0.93986254 | G7: 46000 | H7: 19.5 | I7: Gas | J7: Truck | K7: Yes | L7: 7.7% | M7: 2025 (base 4.8%) | N7: 5.3L AFM lifter/cam failure; 10L80 valve body. GM 10-spd more reliable than Ford's. | O7: =MIN(G7,G7*Depreciation!$C$23*F7) -> 11079.823 | P7: =G7-O7 -> 34920.177 | Q7: =IFERROR(P7/Inputs!$C$8,0) -> 0.24942984 | R7: =IFERROR(IF(I7="Diesel",Inputs!$C$14,Inputs!$C$13)/H7,0) -> 0.18205128 | S7: =IFERROR(IF(J7="Truck",Inputs!$C$16,Inputs!$C$15)/Inputs!$C$17,0) -> 0.023636364 | T7: =Inputs!$C$18 -> 0.08 | U7: =Inputs!$C$29 -> 0.055714286 | V7: =IFERROR(Inputs!$C$19/Inputs!$C$5,0) -> 0.029090909 | W7: =IFERROR(Inputs!$C$20/Inputs!$C$5,0) -> 0.0081818182 | X7: =IFERROR(G7*Inputs!$C$46/Inputs!$C$8,0) -> 0.023 | Y7: =IFERROR((G7+O7)/2*Inputs!$C$33*Inputs!$C$9/Inputs!$C$8,0) -> 0.023350837 | Z7: =IFERROR((G7*(1-Inputs!$C$35)*Inputs!$C$36*Inputs!$C$34*Inputs!$C$9+G7*Inputs!$C$35*Inputs!$C$33*Inputs!$C$9)/Inputs!$C$8,0) -> 0.031447273 | AA7: =IF(Inputs!$C$32="Cash",Y7,Z7) -> 0.023350837 | AB7: =Q7+R7+S7+T7+U7+V7+W7+X7+AA7 -> 0.67445533 | AC7: =AB7*Inputs!$C$8 -> 94423.747 | AD7: =AB7*Inputs!$C$5 -> 37095.043 | AE7: =RANK(AB7,$AB$7:$AB$82,1) -> 66 | AF7: 45.6 | AG7: 63.4 | AH7: 54.5 | AI7: measured | AJ7: =MIN(G7,G7*Depreciation!$E$33*F7) -> 13271.928 | AK7: =IFERROR((G7-AJ7)/(2*Inputs!$C$5),0) -> 0.29752793
A8: Chevrolet Tahoe 3.0L Duramax | B8: Full-size BOF SUV | C8: Tier 1 | D8: 0.453 | E8: iSeeCars 2026 | F8: =(1-D8)/(1-Inputs!$C$54) -> 0.93986254 | G8: 48000 | H8: 27 | I8: Diesel | J8: Truck | K8: Yes | L8: 7.7% | M8: 2025 (base 4.8%) | N8: CAUTION: at Indiana prices ($5.35 diesel vs $3.55 gas) the diesel costs MORE per mile to fuel than the gas V8 despite 27 vs 19.5 mpg. Only wins if the diesel premium narrows below ~$1.15/gal. | O8: =MIN(G8,G8*Depreciation!$C$23*F8) -> 11561.554 | P8: =G8-O8 -> 36438.446 | Q8: =IFERROR(P8/Inputs!$C$8,0) -> 0.26027461 | R8: =IFERROR(IF(I8="Diesel",Inputs!$C$14,Inputs!$C$13)/H8,0) -> 0.19814815 | S8: =IFERROR(IF(J8="Truck",Inputs!$C$16,Inputs!$C$15)/Inputs!$C$17,0) -> 0.023636364 | T8: =Inputs!$C$18 -> 0.08 | U8: =Inputs!$C$29 -> 0.055714286 | V8: =IFERROR(Inputs!$C$19/Inputs!$C$5,0) -> 0.029090909 | W8: =IFERROR(Inputs!$C$20/Inputs!$C$5,0) -> 0.0081818182 | X8: =IFERROR(G8*Inputs!$C$46/Inputs!$C$8,0) -> 0.024 | Y8: =IFERROR((G8+O8)/2*Inputs!$C$33*Inputs!$C$9/Inputs!$C$8,0) -> 0.02436609 | Z8: =IFERROR((G8*(1-Inputs!$C$35)*Inputs!$C$36*Inputs!$C$34*Inputs!$C$9+G8*Inputs!$C$35*Inputs!$C$33*Inputs!$C$9)/Inputs!$C$8,0) -> 0.032814545 | AA8: =IF(Inputs!$C$32="Cash",Y8,Z8) -> 0.02436609 | AB8: =Q8+R8+S8+T8+U8+V8+W8+X8+AA8 -> 0.70341223 | AC8: =AB8*Inputs!$C$8 -> 98477.712 | AD8: =AB8*Inputs!$C$5 -> 38687.673 | AE8: =RANK(AB8,$AB$7:$AB$82,1) -> 70 | AF8: 57.6 | AG8: 63.4 | AH8: 54.5 | AI8: measured | AJ8: =MIN(G8,G8*Depreciation!$E$33*F8) -> 13848.968 | AK8: =IFERROR((G8-AJ8)/(2*Inputs!$C$5),0) -> 0.31046393
A9: Chevrolet Suburban | B9: Full-size BOF SUV | C9: Tier 1 | D9: 0.556 | E9: iSeeCars 2025 | F9: =(1-D9)/(1-Inputs!$C$54) -> 0.7628866 | G9: 45000 | H9: 19 | I9: Gas | J9: Truck | K9: Yes | L9: 11.8% | M9: 2025 (base 4.8%) | N9: Same 5.3L AFM lifter risk as Tahoe. | O9: =MIN(G9,G9*Depreciation!$C$23*F9) -> 8797.9834 | P9: =G9-O9 -> 36202.017 | Q9: =IFERROR(P9/Inputs!$C$8,0) -> 0.25858583 | R9: =IFERROR(IF(I9="Diesel",Inputs!$C$14,Inputs!$C$13)/H9,0) -> 0.18684211 | S9: =IFERROR(IF(J9="Truck",Inputs!$C$16,Inputs!$C$15)/Inputs!$C$17,0) -> 0.023636364 | T9: =Inputs!$C$18 -> 0.08 | U9: =Inputs!$C$29 -> 0.055714286 | V9: =IFERROR(Inputs!$C$19/Inputs!$C$5,0) -> 0.029090909 | W9: =IFERROR(Inputs!$C$20/Inputs!$C$5,0) -> 0.0081818182 | X9: =IFERROR(G9*Inputs!$C$46/Inputs!$C$8,0) -> 0.0225 | Y9: =IFERROR((G9+O9)/2*Inputs!$C$33*Inputs!$C$9/Inputs!$C$8,0) -> 0.022008266 | Z9: =IFERROR((G9*(1-Inputs!$C$35)*Inputs!$C$36*Inputs!$C$34*Inputs!$C$9+G9*Inputs!$C$35*Inputs!$C$33*Inputs!$C$9)/Inputs!$C$8,0) -> 0.030763636 | AA9: =IF(Inputs!$C$32="Cash",Y9,Z9) -> 0.022008266 | AB9: =Q9+R9+S9+T9+U9+V9+W9+X9+AA9 -> 0.68655958 | AC9: =AB9*Inputs!$C$8 -> 96118.341 | AD9: =AB9*Inputs!$C$5 -> 37760.777 | AE9: =RANK(AB9,$AB$7:$AB$82,1) -> 68 | AF9: 45.6 | AG9: 64.4 | AH9: 54.4 | AI9: measured | AJ9: =MIN(G9,G9*Depreciation!$E$33*F9) -> 10538.634 | AK9: =IFERROR((G9-AJ9)/(2*Inputs!$C$5),0) -> 0.31328514
A10: GMC Yukon | B10: Full-size BOF SUV | C10: Tier 1 | D10: 0.48 | E10: iSeeCars 2026 | F10: =(1-D10)/(1-Inputs!$C$54) -> 0.89347079 | G10: 49000 | H10: 19 | I10: Gas | J10: Truck | K10: Yes | L10: 7.8% | M10: 2025 (base 4.8%) | N10: Same AFM lifter risk. GMC badge premium over Tahoe. | O10: =MIN(G10,G10*Depreciation!$C$23*F10) -> 11219.851 | P10: =G10-O10 -> 37780.149 | Q10: =IFERROR(P10/Inputs!$C$8,0) -> 0.26985821 | R10: =IFERROR(IF(I10="Diesel",Inputs!$C$14,Inputs!$C$13)/H10,0) -> 0.18684211 | S10: =IFERROR(IF(J10="Truck",Inputs!$C$16,Inputs!$C$15)/Inputs!$C$17,0) -> 0.023636364 | T10: =Inputs!$C$18 -> 0.08 | U10: =Inputs!$C$29 -> 0.055714286 | V10: =IFERROR(Inputs!$C$19/Inputs!$C$5,0) -> 0.029090909 | W10: =IFERROR(Inputs!$C$20/Inputs!$C$5,0) -> 0.0081818182 | X10: =IFERROR(G10*Inputs!$C$46/Inputs!$C$8,0) -> 0.0245 | Y10: =IFERROR((G10+O10)/2*Inputs!$C$33*Inputs!$C$9/Inputs!$C$8,0) -> 0.024635393 | Z10: =IFERROR((G10*(1-Inputs!$C$35)*Inputs!$C$36*Inputs!$C$34*Inputs!$C$9+G10*Inputs!$C$35*Inputs!$C$33*Inputs!$C$9)/Inputs!$C$8,0) -> 0.033498182 | AA10: =IF(Inputs!$C$32="Cash",Y10,Z10) -> 0.024635393 | AB10: =Q10+R10+S10+T10+U10+V10+W10+X10+AA10 -> 0.70245908 | AC10: =AB10*Inputs!$C$8 -> 98344.272 | AD10: =AB10*Inputs!$C$5 -> 38635.25 | AE10: =RANK(AB10,$AB$7:$AB$82,1) -> 69 | AF10: 29 | AG10: 63.4 | AH10: 54.5 | AI10: measured | AJ10: =MIN(G10,G10*Depreciation!$E$33*F10) -> 13439.66 | AK10: =IFERROR((G10-AJ10)/(2*Inputs!$C$5),0) -> 0.32327582
A11: GMC Yukon XL | B11: Full-size BOF SUV | C11: Tier 1 | D11: 0.48 | E11: iSeeCars 2026 | F11: =(1-D11)/(1-Inputs!$C$54) -> 0.89347079 | G11: 50000 | H11: 19 | I11: Gas | J11: Truck | K11: Yes | L11: 9.0% | M11: 2025 (base 4.8%) | N11: Same AFM lifter risk. | O11: =MIN(G11,G11*Depreciation!$C$23*F11) -> 11448.827 | P11: =G11-O11 -> 38551.173 | Q11: =IFERROR(P11/Inputs!$C$8,0) -> 0.27536552 | R11: =IFERROR(IF(I11="Diesel",Inputs!$C$14,Inputs!$C$13)/H11,0) -> 0.18684211 | S11: =IFERROR(IF(J11="Truck",Inputs!$C$16,Inputs!$C$15)/Inputs!$C$17,0) -> 0.023636364 | T11: =Inputs!$C$18 -> 0.08 | U11: =Inputs!$C$29 -> 0.055714286 | V11: =IFERROR(Inputs!$C$19/Inputs!$C$5,0) -> 0.029090909 | W11: =IFERROR(Inputs!$C$20/Inputs!$C$5,0) -> 0.0081818182 | X11: =IFERROR(G11*Inputs!$C$46/Inputs!$C$8,0) -> 0.025 | Y11: =IFERROR((G11+O11)/2*Inputs!$C$33*Inputs!$C$9/Inputs!$C$8,0) -> 0.025138157 | Z11: =IFERROR((G11*(1-Inputs!$C$35)*Inputs!$C$36*Inputs!$C$34*Inputs!$C$9+G11*Inputs!$C$35*Inputs!$C$33*Inputs!$C$9)/Inputs!$C$8,0) -> 0.034181818 | AA11: =IF(Inputs!$C$32="Cash",Y11,Z11) -> 0.025138157 | AB11: =Q11+R11+S11+T11+U11+V11+W11+X11+AA11 -> 0.70896916 | AC11: =AB11*Inputs!$C$8 -> 99255.682 | AD11: =AB11*Inputs!$C$5 -> 38993.304 | AE11: =RANK(AB11,$AB$7:$AB$82,1) -> 71 | AF11: 29 | AG11: 63.4 | AH11: 54.5 | AI11: measured | AJ11: =MIN(G11,G11*Depreciation!$E$33*F11) -> 13713.938 | AK11: =IFERROR((G11-AJ11)/(2*Inputs!$C$5),0) -> 0.32987329
A12: Ford Expedition | B12: Full-size BOF SUV | C12: Tier 2 | D12: 0.6 | E12: iSeeCars 2025 | F12: =(1-D12)/(1-Inputs!$C$54) -> 0.68728522 | G12: 43000 | H12: 18.5 | I12: Gas | J12: Truck | K12: Yes | L12: 19.9% | M12: 2023 (base 11.8%) | N12: Gen2 3.5 EcoBoost cam-phaser rattle 2018+ ($3.5k-$5.5k) AND 10R80 10-speed. Two known risks stacked. | O12: =MIN(G12,G12*Depreciation!$C$23*F12) -> 7573.8395 | P12: =G12-O12 -> 35426.16 | Q12: =IFERROR(P12/Inputs!$C$8,0) -> 0.253044 | R12: =IFERROR(IF(I12="Diesel",Inputs!$C$14,Inputs!$C$13)/H12,0) -> 0.19189189 | S12: =IFERROR(IF(J12="Truck",Inputs!$C$16,Inputs!$C$15)/Inputs!$C$17,0) -> 0.023636364 | T12: =Inputs!$C$18 -> 0.08 | U12: =Inputs!$C$29 -> 0.055714286 | V12: =IFERROR(Inputs!$C$19/Inputs!$C$5,0) -> 0.029090909 | W12: =IFERROR(Inputs!$C$20/Inputs!$C$5,0) -> 0.0081818182 | X12: =IFERROR(G12*Inputs!$C$46/Inputs!$C$8,0) -> 0.0215 | Y12: =IFERROR((G12+O12)/2*Inputs!$C$33*Inputs!$C$9/Inputs!$C$8,0) -> 0.020689298 | Z12: =IFERROR((G12*(1-Inputs!$C$35)*Inputs!$C$36*Inputs!$C$34*Inputs!$C$9+G12*Inputs!$C$35*Inputs!$C$33*Inputs!$C$9)/Inputs!$C$8,0) -> 0.029396364 | AA12: =IF(Inputs!$C$32="Cash",Y12,Z12) -> 0.020689298 | AB12: =Q12+R12+S12+T12+U12+V12+W12+X12+AA12 -> 0.68374857 | AC12: =AB12*Inputs!$C$8 -> 95724.8 | AD12: =AB12*Inputs!$C$5 -> 37606.171 | AE12: =RANK(AB12,$AB$7:$AB$82,1) -> 67 | AF12: 52.7 | AG12: 64.4 | AH12: 54.4 | AI12: measured | AJ12: =MIN(G12,G12*Depreciation!$E$33*F12) -> 9072.2977 | AK12: =IFERROR((G12-AJ12)/(2*Inputs!$C$5),0) -> 0.30843366
A13: Toyota Sequoia (pre-2023 5.7 V8) | B13: Full-size BOF SUV | C13: Tier 1 | D13: 0.42 | E13: segment est. | F13: =(1-D13)/(1-Inputs!$C$54) -> 0.99656357 | G13: 46000 | H13: 15.5 | I13: Gas | J13: Truck | K13: Yes | L13: 39.1% | M13: 2025 (base 4.8%) | N13: #1 longest-lasting vehicle in the 2025 study, 8x the industry average. Worst fuel economy here. | O13: =MIN(G13,G13*Depreciation!$C$23*F13) -> 11748.258 | P13: =G13-O13 -> 34251.742 | Q13: =IFERROR(P13/Inputs!$C$8,0) -> 0.2446553 | R13: =IFERROR(IF(I13="Diesel",Inputs!$C$14,Inputs!$C$13)/H13,0) -> 0.22903226 | S13: =IFERROR(IF(J13="Truck",Inputs!$C$16,Inputs!$C$15)/Inputs!$C$17,0) -> 0.023636364 | T13: =Inputs!$C$18 -> 0.08 | U13: =Inputs!$C$29 -> 0.055714286 | V13: =IFERROR(Inputs!$C$19/Inputs!$C$5,0) -> 0.029090909 | W13: =IFERROR(Inputs!$C$20/Inputs!$C$5,0) -> 0.0081818182 | X13: =IFERROR(G13*Inputs!$C$46/Inputs!$C$8,0) -> 0.023 | Y13: =IFERROR((G13+O13)/2*Inputs!$C$33*Inputs!$C$9/Inputs!$C$8,0) -> 0.023624287 | Z13: =IFERROR((G13*(1-Inputs!$C$35)*Inputs!$C$36*Inputs!$C$34*Inputs!$C$9+G13*Inputs!$C$35*Inputs!$C$33*Inputs!$C$9)/Inputs!$C$8,0) -> 0.031447273 | AA13: =IF(Inputs!$C$32="Cash",Y13,Z13) -> 0.023624287 | AB13: =Q13+R13+S13+T13+U13+V13+W13+X13+AA13 -> 0.71693522 | AC13: =AB13*Inputs!$C$8 -> 100370.93 | AD13: =AB13*Inputs!$C$5 -> 39431.437 | AE13: =RANK(AB13,$AB$7:$AB$82,1) -> 73 | AF13: 100 | AG13: 52.3 | AH13: 55.7 | AI13: measured | AJ13: =MIN(G13,G13*Depreciation!$E$33*F13) -> 14072.611 | AK13: =IFERROR((G13-AJ13)/(2*Inputs!$C$5),0) -> 0.29024899
A14: Nissan Armada | B14: Full-size BOF SUV | C14: Tier 2 | D14: 0.6 | E14: iSeeCars 2025 | F14: =(1-D14)/(1-Inputs!$C$54) -> 0.68728522 | G14: 32000 | H14: 17 | I14: Gas | J14: Truck | K14: Yes | L14: 5.8% | M14: 2025 (base 4.8%) | N14: 5.6L V8 + 7-spd conventional, NOT a CVT. Durable but weak resale - that's the cheap-buy opening. | O14: =MIN(G14,G14*Depreciation!$C$23*F14) -> 5636.3457 | P14: =G14-O14 -> 26363.654 | Q14: =IFERROR(P14/Inputs!$C$8,0) -> 0.18831182 | R14: =IFERROR(IF(I14="Diesel",Inputs!$C$14,Inputs!$C$13)/H14,0) -> 0.20882353 | S14: =IFERROR(IF(J14="Truck",Inputs!$C$16,Inputs!$C$15)/Inputs!$C$17,0) -> 0.023636364 | T14: =Inputs!$C$18 -> 0.08 | U14: =Inputs!$C$29 -> 0.055714286 | V14: =IFERROR(Inputs!$C$19/Inputs!$C$5,0) -> 0.029090909 | W14: =IFERROR(Inputs!$C$20/Inputs!$C$5,0) -> 0.0081818182 | X14: =IFERROR(G14*Inputs!$C$46/Inputs!$C$8,0) -> 0.016 | Y14: =IFERROR((G14+O14)/2*Inputs!$C$33*Inputs!$C$9/Inputs!$C$8,0) -> 0.015396687 | Z14: =IFERROR((G14*(1-Inputs!$C$35)*Inputs!$C$36*Inputs!$C$34*Inputs!$C$9+G14*Inputs!$C$35*Inputs!$C$33*Inputs!$C$9)/Inputs!$C$8,0) -> 0.021876364 | AA14: =IF(Inputs!$C$32="Cash",Y14,Z14) -> 0.015396687 | AB14: =Q14+R14+S14+T14+U14+V14+W14+X14+AA14 -> 0.62515541 | AC14: =AB14*Inputs!$C$8 -> 87521.757 | AD14: =AB14*Inputs!$C$5 -> 34383.548 | AE14: =RANK(AB14,$AB$7:$AB$82,1) -> 64 | AF14: 86.4 | AG14: 58.8 | AH14: 55 | AI14: measured | AJ14: =MIN(G14,G14*Depreciation!$E$33*F14) -> 6751.4774 | AK14: =IFERROR((G14-AJ14)/(2*Inputs!$C$5),0) -> 0.22953202
A15: Cadillac Escalade | B15: Full-size BOF SUV | C15: Tier 3 | D15: 0.618 | E15: iSeeCars 2025 | F15: =(1-D15)/(1-Inputs!$C$54) -> 0.65635739 | G15: 70000 | H15: 17 | I15: Gas | J15: Truck | K15: Yes | L15: 6.8% | M15: 2025 ESV (base 4.8%) | N15: Luxury depreciation plus air suspension and electronics. Wrong tool at this mileage. | O15: =MIN(G15,G15*Depreciation!$C$23*F15) -> 11774.678 | P15: =G15-O15 -> 58225.322 | Q15: =IFERROR(P15/Inputs!$C$8,0) -> 0.41589515 | R15: =IFERROR(IF(I15="Diesel",Inputs!$C$14,Inputs!$C$13)/H15,0) -> 0.20882353 | S15: =IFERROR(IF(J15="Truck",Inputs!$C$16,Inputs!$C$15)/Inputs!$C$17,0) -> 0.023636364 | T15: =Inputs!$C$18 -> 0.08 | U15: =Inputs!$C$29 -> 0.055714286 | V15: =IFERROR(Inputs!$C$19/Inputs!$C$5,0) -> 0.029090909 | W15: =IFERROR(Inputs!$C$20/Inputs!$C$5,0) -> 0.0081818182 | X15: =IFERROR(G15*Inputs!$C$46/Inputs!$C$8,0) -> 0.035 | Y15: =IFERROR((G15+O15)/2*Inputs!$C$33*Inputs!$C$9/Inputs!$C$8,0) -> 0.033453278 | Z15: =IFERROR((G15*(1-Inputs!$C$35)*Inputs!$C$36*Inputs!$C$34*Inputs!$C$9+G15*Inputs!$C$35*Inputs!$C$33*Inputs!$C$9)/Inputs!$C$8,0) -> 0.047854545 | AA15: =IF(Inputs!$C$32="Cash",Y15,Z15) -> 0.033453278 | AB15: =Q15+R15+S15+T15+U15+V15+W15+X15+AA15 -> 0.88979534 | AC15: =AB15*Inputs!$C$8 -> 124571.35 | AD15: =AB15*Inputs!$C$5 -> 48938.744 | AE15: =RANK(AB15,$AB$7:$AB$82,1) -> 76 | AF15: 44.1 | AG15: 54.2 | AH15: 55.5 | AI15: measured | AJ15: =MIN(G15,G15*Depreciation!$E$33*F15) -> 14104.258 | AK15: =IFERROR((G15-AJ15)/(2*Inputs!$C$5),0) -> 0.50814311
A16: Jeep Grand Wagoneer | B16: Full-size BOF SUV | C16: Tier 3 | D16: 0.56 | E16: estimate | F16: =(1-D16)/(1-Inputs!$C$54) -> 0.75601375 | G16: 54000 | H16: 16.5 | I16: Gas | J16: Truck | K16: Yes | L16: n/a | M16: not available | N16: New platform, thin high-mileage data, luxury electronics risk. | O16: =MIN(G16,G16*Depreciation!$C$23*F16) -> 10462.467 | P16: =G16-O16 -> 43537.533 | Q16: =IFERROR(P16/Inputs!$C$8,0) -> 0.31098238 | R16: =IFERROR(IF(I16="Diesel",Inputs!$C$14,Inputs!$C$13)/H16,0) -> 0.21515152 | S16: =IFERROR(IF(J16="Truck",Inputs!$C$16,Inputs!$C$15)/Inputs!$C$17,0) -> 0.023636364 | T16: =Inputs!$C$18 -> 0.08 | U16: =Inputs!$C$29 -> 0.055714286 | V16: =IFERROR(Inputs!$C$19/Inputs!$C$5,0) -> 0.029090909 | W16: =IFERROR(Inputs!$C$20/Inputs!$C$5,0) -> 0.0081818182 | X16: =IFERROR(G16*Inputs!$C$46/Inputs!$C$8,0) -> 0.027 | Y16: =IFERROR((G16+O16)/2*Inputs!$C$33*Inputs!$C$9/Inputs!$C$8,0) -> 0.026371009 | Z16: =IFERROR((G16*(1-Inputs!$C$35)*Inputs!$C$36*Inputs!$C$34*Inputs!$C$9+G16*Inputs!$C$35*Inputs!$C$33*Inputs!$C$9)/Inputs!$C$8,0) -> 0.036916364 | AA16: =IF(Inputs!$C$32="Cash",Y16,Z16) -> 0.026371009 | AB16: =Q16+R16+S16+T16+U16+V16+W16+X16+AA16 -> 0.77612828 | AC16: =AB16*Inputs!$C$8 -> 108657.96 | AD16: =AB16*Inputs!$C$5 -> 42687.055 | AE16: =RANK(AB16,$AB$7:$AB$82,1) -> 74 | AF16: 28.4 | AG16: 31 | AH16: 58 | AI16: measured | AJ16: =MIN(G16,G16*Depreciation!$E$33*F16) -> 12532.43 | AK16: =IFERROR((G16-AJ16)/(2*Inputs!$C$5),0) -> 0.37697791
A17: Jeep Grand Cherokee | B17: Mid-size SUV | C17: Tier 2 | D17: 0.51 | E17: 2025 segment | F17: =(1-D17)/(1-Inputs!$C$54) -> 0.8419244 | G17: 32000 | H17: 23 | I17: Gas | J17: Crossover | K17: Yes | L17: n/a | M17: not available | N17: ZF 8HP is strong BUT flush it at 60k - Jeep calls it lifetime fill. 2021+ WL 850RE early clutch faults. | O17: =MIN(G17,G17*Depreciation!$C$23*F17) -> 6904.5235 | P17: =G17-O17 -> 25095.477 | Q17: =IFERROR(P17/Inputs!$C$8,0) -> 0.1792534 | R17: =IFERROR(IF(I17="Diesel",Inputs!$C$14,Inputs!$C$13)/H17,0) -> 0.15434783 | S17: =IFERROR(IF(J17="Truck",Inputs!$C$16,Inputs!$C$15)/Inputs!$C$17,0) -> 0.016363636 | T17: =Inputs!$C$18 -> 0.08 | U17: =Inputs!$C$29 -> 0.055714286 | V17: =IFERROR(Inputs!$C$19/Inputs!$C$5,0) -> 0.029090909 | W17: =IFERROR(Inputs!$C$20/Inputs!$C$5,0) -> 0.0081818182 | X17: =IFERROR(G17*Inputs!$C$46/Inputs!$C$8,0) -> 0.016 | Y17: =IFERROR((G17+O17)/2*Inputs!$C$33*Inputs!$C$9/Inputs!$C$8,0) -> 0.015915487 | Z17: =IFERROR((G17*(1-Inputs!$C$35)*Inputs!$C$36*Inputs!$C$34*Inputs!$C$9+G17*Inputs!$C$35*Inputs!$C$33*Inputs!$C$9)/Inputs!$C$8,0) -> 0.021876364 | AA17: =IF(Inputs!$C$32="Cash",Y17,Z17) -> 0.015915487 | AB17: =Q17+R17+S17+T17+U17+V17+W17+X17+AA17 -> 0.55486737 | AC17: =AB17*Inputs!$C$8 -> 77681.431 | AD17: =AB17*Inputs!$C$5 -> 30517.705 | AE17: =RANK(AB17,$AB$7:$AB$82,1) -> 42 | AF17: 30.4 | AG17: 64.8 | AH17: 55 | AI17: estimated | AJ17: =MIN(G17,G17*Depreciation!$E$33*F17) -> 8270.5598 | AK17: =IFERROR((G17-AJ17)/(2*Inputs!$C$5),0) -> 0.21572218
A18: Jeep Grand Cherokee L | B18: 3-row crossover | C18: Tier 2 | D18: 0.51 | E18: 2025 segment | F18: =(1-D18)/(1-Inputs!$C$54) -> 0.8419244 | G18: 38000 | H18: 22.5 | I18: Gas | J18: Crossover | K18: Yes | L18: n/a | M18: not available | N18: Same ZF 8HP / 850RE concerns as Grand Cherokee. | O18: =MIN(G18,G18*Depreciation!$C$23*F18) -> 8199.1216 | P18: =G18-O18 -> 29800.878 | Q18: =IFERROR(P18/Inputs!$C$8,0) -> 0.21286342 | R18: =IFERROR(IF(I18="Diesel",Inputs!$C$14,Inputs!$C$13)/H18,0) -> 0.15777778 | S18: =IFERROR(IF(J18="Truck",Inputs!$C$16,Inputs!$C$15)/Inputs!$C$17,0) -> 0.016363636 | T18: =Inputs!$C$18 -> 0.08 | U18: =Inputs!$C$29 -> 0.055714286 | V18: =IFERROR(Inputs!$C$19/Inputs!$C$5,0) -> 0.029090909 | W18: =IFERROR(Inputs!$C$20/Inputs!$C$5,0) -> 0.0081818182 | X18: =IFERROR(G18*Inputs!$C$46/Inputs!$C$8,0) -> 0.019 | Y18: =IFERROR((G18+O18)/2*Inputs!$C$33*Inputs!$C$9/Inputs!$C$8,0) -> 0.018899641 | Z18: =IFERROR((G18*(1-Inputs!$C$35)*Inputs!$C$36*Inputs!$C$34*Inputs!$C$9+G18*Inputs!$C$35*Inputs!$C$33*Inputs!$C$9)/Inputs!$C$8,0) -> 0.025978182 | AA18: =IF(Inputs!$C$32="Cash",Y18,Z18) -> 0.018899641 | AB18: =Q18+R18+S18+T18+U18+V18+W18+X18+AA18 -> 0.59789148 | AC18: =AB18*Inputs!$C$8 -> 83704.808 | AD18: =AB18*Inputs!$C$5 -> 32884.032 | AE18: =RANK(AB18,$AB$7:$AB$82,1) -> 56 | AF18: 30.4 | AG18: 64.8 | AH18: 55 | AI18: estimated | AJ18: =MIN(G18,G18*Depreciation!$E$33*F18) -> 9821.2897 | AK18: =IFERROR((G18-AJ18)/(2*Inputs!$C$5),0) -> 0.25617009
... A82: Ram 2500 (Cummins) | B82: Heavy-duty truck | C82: Tier 2 | D82: 0.4 | E82: estimate | F82: =(1-D82)/(1-Inputs!$C$54) -> 1.0309278 | G82: 52000 | H82: 19 | I82: Diesel | J82: Truck | K82: Yes (10,000) | L82: 17.3% | M82: 2025 (base 4.8%) | N82: Cummins I6 durability is legendary. CP4 pump risk on 2019+. Diesel fuel cost is the drag. | O82: =MIN(G82,G82*Depreciation!$C$23*F82) -> 13738.593 | P82: =G82-O82 -> 38261.407 | Q82: =IFERROR(P82/Inputs!$C$8,0) -> 0.27329577 | R82: =IFERROR(IF(I82="Diesel",Inputs!$C$14,Inputs!$C$13)/H82,0) -> 0.28157895 | S82: =IFERROR(IF(J82="Truck",Inputs!$C$16,Inputs!$C$15)/Inputs!$C$17,0) -> 0.023636364 | T82: =Inputs!$C$18 -> 0.08 | U82: =Inputs!$C$29 -> 0.055714286 | V82: =IFERROR(Inputs!$C$19/Inputs!$C$5,0) -> 0.029090909 | W82: =IFERROR(Inputs!$C$20/Inputs!$C$5,0) -> 0.0081818182 | X82: =IFERROR(G82*Inputs!$C$46/Inputs!$C$8,0) -> 0.026 | Y82: =IFERROR((G82+O82)/2*Inputs!$C$33*Inputs!$C$9/Inputs!$C$8,0) -> 0.026893061 | Z82: =IFERROR((G82*(1-Inputs!$C$35)*Inputs!$C$36*Inputs!$C$34*Inputs!$C$9+G82*Inputs!$C$35*Inputs!$C$33*Inputs!$C$9)/Inputs!$C$8,0) -> 0.035549091 | AA82: =IF(Inputs!$C$32="Cash",Y82,Z82) -> 0.026893061 | AB82: =Q82+R82+S82+T82+U82+V82+W82+X82+AA82 -> 0.80439115 | AC82: =AB82*Inputs!$C$8 -> 112614.76 | AD82: =AB82*Inputs!$C$5 -> 44241.513 | AE82: =RANK(AB82,$AB$7:$AB$82,1) -> 75 | AF82: 33.4 | AG82: 32.9 | AH82: 57.8 | AI82: measured | AJ82: =MIN(G82,G82*Depreciation!$E$33*F82) -> 16456.726 | AK82: =IFERROR((G82-AJ82)/(2*Inputs!$C$5),0) -> 0.32312067
A84: TIER KEY
A85: Tier 1 | B85: Proven high-mileage durability, no transmission red flag. Buy with confidence.
A86: Tier 2 | B86: Viable with a caveat — one component to watch, a fuel-cost drag, or a service requirement you must document.
A87: Tier 3 | B87: Poor 180,000-mile bet. Documented transmission or turbo weakness, or fuel/luxury costs that dominate. Avoid or research hard.
A89: • DEPRECIATION FIGURES MIX STUDY YEARS AND ARE NOT DIRECTLY COMPARABLE. The iSeeCars industry baseline moved: 38.8% (2023), 45.6% (2025), 41.8% (2026). Column E names the source for every row. A 2025-study figure sits against a 45.6% baseline; a 2026-study figure against 41.8%. Rows marked '2025 segment' or 'estimate' had no individual breakout — treat those resale multipliers as weak.
A90: • 250,000-MILE ODDS ARE ALSO NOT COMPARABLE ACROSS YEARS. The baseline collapsed from 11.8% (2023) to 8.6% (2024) to 4.8% (2025). Column M gives the study year and that year's baseline so you can read each figure against the right denominator. Rankings hold across years even though absolute percentages do not.
A91: • CVT WARNING. Nissan Rogue (2014-2018), Pathfinder (2013-2020), and Murano use the Jatco CVT that produced a $277.7 million class settlement (Stringer v. Nissan) with powertrain warranty extended to 84 months / 84,000 miles. Subaru and Honda CVTs have better records but still need fluid every 30-60k. Toyota, Lexus, and Ford hybrid 'eCVT' units are planetary power-split devices, NOT belt CVTs — they are among the most durable transmissions on the road. Do not confuse the two.
A92: • OTHER TRANSMISSION RED FLAGS. ZF 9HP (Jeep Cherokee, Compass, Renegade): 7,000+ complaints on 2014-15 Cherokees alone, 82,000-unit recall. Ford 10R80 10-speed (Explorer, Ranger, F-150, Expedition): rebuild $3,800-$5,200. GM's 10L80 has a notably better record than Ford's 10R80.
A93: • SECTION 179 SURPRISE. The Kia Telluride (5,776-5,917 lb) and Hyundai Palisade (5,700-5,900 lb) are UNDER 6,000 lb GVWR despite their size, so they do NOT qualify for the heavy-vehicle treatment. Honda Pilot, Chevy Traverse, GMC Acadia, and Grand Highlander straddle the line by trim and drivetrain. The door-jamb Safety Compliance sticker is the only authoritative source — pull a photo before you buy.
A94: • FULL-SIZE SUV MATH. At 55,000 mi/yr, a 17 mpg full-size SUV burns about 3,235 gallons a year against 1,964 for a 28 mpg crossover. At $3.55/gal that is roughly a $4,500/yr fuel penalty. Best-in-segment resale recovers only part of it. A gas Tahoe/Yukon is justified only if you genuinely need the tow rating, eight or nine seats, or body-on-frame durability. The 3.0L Duramax is NOT the escape hatch it looks like: at Indiana's $5.35 diesel vs $3.55 gas, 27 mpg diesel costs $0.198/mi against $0.182/mi for the 19.5 mpg gas V8. The diesel only wins if the per-gallon premium falls below about $1.15. Check both fuel prices before assuming diesel saves money.

Sheet Strategies
A1: Turnover Strategy Comparison
A2: Same cost engine, different buy and sell points. Answers 'when do I turn over', not 'what do I buy'.
A4: Strategy | B4: Buy odo | C4: Sell odo | D4: Purchase price | E4: Cycle miles | F4: Years | G4: Idx buy | H4: Idx sell | I4: Est. resale | J4: Deprec. $ | K4: Deprec. $/mi | L4: Mi <100k | M4: Mi 100-150k | N4: Mi >150k | O4: Repair $/mi | P4: Fuel $/mi | Q4: Tires $/mi | R4: Maint $/mi | S4: Ins+reg $/mi | T4: Sales tax $/mi | U4: Capital $/mi | V4: TOTAL $/mi | W4: Cost per year
A5: A — Buy 40k, sell 150k (24 mo) | B5: 40000 | C5: 150000 | D5: 26000 | E5: =C5-B5 -> 110000 | F5: =IFERROR(E5/Inputs!$C$5,0) -> 2 | G5: =IFERROR(INDEX(Depreciation!$D$5:$D$14,MATCH(B5,Depreciation!$B$5:$B$14,1))+(B5-INDEX(Depreciation!$B$5:$B$14,MATCH(B5,Depreciation!$B$5:$B$14,1)))/(INDEX(Depreciation!$B$5:$B$14,MATCH(B5,Depreciation!$B$5:$B$14,1)+1)-INDEX(Depreciation!$B$5:$B$14,MATCH(B5,Depreciation!$B$5:$B$14,1)))*(INDEX(Depreciation!$D$5:$D$14,MATCH(B5,Depreciation!$B$5:$B$14,1)+1)-INDEX(Depreciation!$D$5:$D$14,MATCH(B5,Depreciation!$B$5:$B$14,1))),INDEX(Depreciation!$D$5:$D$14,MATCH(B5,Depreciation!$B$5:$B$14,1))) -> 0.82834286 | H5: =IFERROR(INDEX(Depreciation!$D$5:$D$14,MATCH(C5,Depreciation!$B$5:$B$14,1))+(C5-INDEX(Depreciation!$B$5:$B$14,MATCH(C5,Depreciation!$B$5:$B$14,1)))/(INDEX(Depreciation!$B$5:$B$14,MATCH(C5,Depreciation!$B$5:$B$14,1)+1)-INDEX(Depreciation!$B$5:$B$14,MATCH(C5,Depreciation!$B$5:$B$14,1)))*(INDEX(Depreciation!$D$5:$D$14,MATCH(C5,Depreciation!$B$5:$B$14,1)+1)-INDEX(Depreciation!$D$5:$D$14,MATCH(C5,Depreciation!$B$5:$B$14,1))),INDEX(Depreciation!$D$5:$D$14,MATCH(C5,Depreciation!$B$5:$B$14,1))) -> 0.25428571 | I5: =IFERROR(MIN(D5,D5*H5/G5),0) -> 7981.5121 | J5: =D5-I5 -> 18018.488 | K5: =IFERROR(J5/E5,0) -> 0.16380444 | L5: =MAX(0,MIN(C5,100000)-B5) -> 60000 | M5: =MAX(0,MIN(C5,150000)-MAX(B5,100000)) -> 50000 | N5: =MAX(0,C5-MAX(B5,150000)) -> 0 | O5: =IFERROR((L5*Inputs!$C$23+M5*Inputs!$C$24+N5*Inputs!$C$25)/E5,0) -> 0.043636364 | P5: =IFERROR(Inputs!$C$13/24,0) -> 0.14791667 | Q5: =IFERROR(Inputs!$C$15/Inputs!$C$17,0) -> 0.016363636 | R5: =Inputs!$C$18 -> 0.08 | S5: =IFERROR((Inputs!$C$19+Inputs!$C$20)/Inputs!$C$5,0) -> 0.037272727 | T5: =IFERROR(D5*Inputs!$C$46/E5,0) -> 0.016545455 | U5: =IFERROR(IF(Inputs!$C$32="Cash",(D5+I5)/2*Inputs!$C$33*F5,(D5*(1-Inputs!$C$35)*Inputs!$C$36*Inputs!$C$34*F5+D5*Inputs!$C$35*Inputs!$C$33*F5))/E5,0) -> 0.013901528 | V5: =K5+O5+P5+Q5+R5+S5+T5+U5 -> 0.51944081 | W5: =V5*Inputs!$C$5 -> 28569.245
A6: B — Buy 40k, sell 180k (30 mo) | B6: 40000 | C6: 180000 | D6: 26000 | E6: =C6-B6 -> 140000 | F6: =IFERROR(E6/Inputs!$C$5,0) -> 2.5454545 | G6: =IFERROR(INDEX(Depreciation!$D$5:$D$14,MATCH(B6,Depreciation!$B$5:$B$14,1))+(B6-INDEX(Depreciation!$B$5:$B$14,MATCH(B6,Depreciation!$B$5:$B$14,1)))/(INDEX(Depreciation!$B$5:$B$14,MATCH(B6,Depreciation!$B$5:$B$14,1)+1)-INDEX(Depreciation!$B$5:$B$14,MATCH(B6,Depreciation!$B$5:$B$14,1)))*(INDEX(Depreciation!$D$5:$D$14,MATCH(B6,Depreciation!$B$5:$B$14,1)+1)-INDEX(Depreciation!$D$5:$D$14,MATCH(B6,Depreciation!$B$5:$B$14,1))),INDEX(Depreciation!$D$5:$D$14,MATCH(B6,Depreciation!$B$5:$B$14,1))) -> 0.82834286 | H6: =IFERROR(INDEX(Depreciation!$D$5:$D$14,MATCH(C6,Depreciation!$B$5:$B$14,1))+(C6-INDEX(Depreciation!$B$5:$B$14,MATCH(C6,Depreciation!$B$5:$B$14,1)))/(INDEX(Depreciation!$B$5:$B$14,MATCH(C6,Depreciation!$B$5:$B$14,1)+1)-INDEX(Depreciation!$B$5:$B$14,MATCH(C6,Depreciation!$B$5:$B$14,1)))*(INDEX(Depreciation!$D$5:$D$14,MATCH(C6,Depreciation!$B$5:$B$14,1)+1)-INDEX(Depreciation!$D$5:$D$14,MATCH(C6,Depreciation!$B$5:$B$14,1))),INDEX(Depreciation!$D$5:$D$14,MATCH(C6,Depreciation!$B$5:$B$14,1))) -> 0.21228571 | I6: =IFERROR(MIN(D6,D6*H6/G6),0) -> 6663.2174 | J6: =D6-I6 -> 19336.783 | K6: =IFERROR(J6/E6,0) -> 0.13811988 | L6: =MAX(0,MIN(C6,100000)-B6) -> 60000 | M6: =MAX(0,MIN(C6,150000)-MAX(B6,100000)) -> 50000 | N6: =MAX(0,C6-MAX(B6,150000)) -> 30000 | O6: =IFERROR((L6*Inputs!$C$23+M6*Inputs!$C$24+N6*Inputs!$C$25)/E6,0) -> 0.055714286 | P6: =IFERROR(Inputs!$C$13/24,0) -> 0.14791667 | Q6: =IFERROR(Inputs!$C$15/Inputs!$C$17,0) -> 0.016363636 | R6: =Inputs!$C$18 -> 0.08 | S6: =IFERROR((Inputs!$C$19+Inputs!$C$20)/Inputs!$C$5,0) -> 0.037272727 | T6: =IFERROR(D6*Inputs!$C$46/E6,0) -> 0.013 | U6: =IFERROR(IF(Inputs!$C$32="Cash",(D6+I6)/2*Inputs!$C$33*F6,(D6*(1-Inputs!$C$35)*Inputs!$C$36*Inputs!$C$34*F6+D6*Inputs!$C$35*Inputs!$C$33*F6))/E6,0) -> 0.013362225 | V6: =K6+O6+P6+Q6+R6+S6+T6+U6 -> 0.50174942 | W6: =V6*Inputs!$C$5 -> 27596.218
A7: C — Buy 70k, sell 180k (24 mo) | B7: 70000 | C7: 180000 | D7: 19000 | E7: =C7-B7 -> 110000 | F7: =IFERROR(E7/Inputs!$C$5,0) -> 2 | G7: =IFERROR(INDEX(Depreciation!$D$5:$D$14,MATCH(B7,Depreciation!$B$5:$B$14,1))+(B7-INDEX(Depreciation!$B$5:$B$14,MATCH(B7,Depreciation!$B$5:$B$14,1)))/(INDEX(Depreciation!$B$5:$B$14,MATCH(B7,Depreciation!$B$5:$B$14,1)+1)-INDEX(Depreciation!$B$5:$B$14,MATCH(B7,Depreciation!$B$5:$B$14,1)))*(INDEX(Depreciation!$D$5:$D$14,MATCH(B7,Depreciation!$B$5:$B$14,1)+1)-INDEX(Depreciation!$D$5:$D$14,MATCH(B7,Depreciation!$B$5:$B$14,1))),INDEX(Depreciation!$D$5:$D$14,MATCH(B7,Depreciation!$B$5:$B$14,1))) -> 0.58274286 | H7: =IFERROR(INDEX(Depreciation!$D$5:$D$14,MATCH(C7,Depreciation!$B$5:$B$14,1))+(C7-INDEX(Depreciation!$B$5:$B$14,MATCH(C7,Depreciation!$B$5:$B$14,1)))/(INDEX(Depreciation!$B$5:$B$14,MATCH(C7,Depreciation!$B$5:$B$14,1)+1)-INDEX(Depreciation!$B$5:$B$14,MATCH(C7,Depreciation!$B$5:$B$14,1)))*(INDEX(Depreciation!$D$5:$D$14,MATCH(C7,Depreciation!$B$5:$B$14,1)+1)-INDEX(Depreciation!$D$5:$D$14,MATCH(C7,Depreciation!$B$5:$B$14,1))),INDEX(Depreciation!$D$5:$D$14,MATCH(C7,Depreciation!$B$5:$B$14,1))) -> 0.21228571 | I7: =IFERROR(MIN(D7,D7*H7/G7),0) -> 6921.4552 | J7: =D7-I7 -> 12078.545 | K7: =IFERROR(J7/E7,0) -> 0.10980495 | L7: =MAX(0,MIN(C7,100000)-B7) -> 30000 | M7: =MAX(0,MIN(C7,150000)-MAX(B7,100000)) -> 50000 | N7: =MAX(0,C7-MAX(B7,150000)) -> 30000 | O7: =IFERROR((L7*Inputs!$C$23+M7*Inputs!$C$24+N7*Inputs!$C$25)/E7,0) -> 0.062727273 | P7: =IFERROR(Inputs!$C$13/24,0) -> 0.14791667 | Q7: =IFERROR(Inputs!$C$15/Inputs!$C$17,0) -> 0.016363636 | R7: =Inputs!$C$18 -> 0.08 | S7: =IFERROR((Inputs!$C$19+Inputs!$C$20)/Inputs!$C$5,0) -> 0.037272727 | T7: =IFERROR(D7*Inputs!$C$46/E7,0) -> 0.012090909 | U7: =IFERROR(IF(Inputs!$C$32="Cash",(D7+I7)/2*Inputs!$C$33*F7,(D7*(1-Inputs!$C$35)*Inputs!$C$36*Inputs!$C$34*F7+D7*Inputs!$C$35*Inputs!$C$33*F7))/E7,0) -> 0.010604232 | V7: =K7+O7+P7+Q7+R7+S7+T7+U7 -> 0.4767804 | W7: =V7*Inputs!$C$5 -> 26222.922
A8: D — Buy 100k, run to 210k (24 mo) | B8: 100000 | C8: 210000 | D8: 11000 | E8: =C8-B8 -> 110000 | F8: =IFERROR(E8/Inputs!$C$5,0) -> 2 | G8: =IFERROR(INDEX(Depreciation!$D$5:$D$14,MATCH(B8,Depreciation!$B$5:$B$14,1))+(B8-INDEX(Depreciation!$B$5:$B$14,MATCH(B8,Depreciation!$B$5:$B$14,1)))/(INDEX(Depreciation!$B$5:$B$14,MATCH(B8,Depreciation!$B$5:$B$14,1)+1)-INDEX(Depreciation!$B$5:$B$14,MATCH(B8,Depreciation!$B$5:$B$14,1)))*(INDEX(Depreciation!$D$5:$D$14,MATCH(B8,Depreciation!$B$5:$B$14,1)+1)-INDEX(Depreciation!$D$5:$D$14,MATCH(B8,Depreciation!$B$5:$B$14,1))),INDEX(Depreciation!$D$5:$D$14,MATCH(B8,Depreciation!$B$5:$B$14,1))) -> 0.41428571 | H8: =IFERROR(INDEX(Depreciation!$D$5:$D$14,MATCH(C8,Depreciation!$B$5:$B$14,1))+(C8-INDEX(Depreciation!$B$5:$B$14,MATCH(C8,Depreciation!$B$5:$B$14,1)))/(INDEX(Depreciation!$B$5:$B$14,MATCH(C8,Depreciation!$B$5:$B$14,1)+1)-INDEX(Depreciation!$B$5:$B$14,MATCH(C8,Depreciation!$B$5:$B$14,1)))*(INDEX(Depreciation!$D$5:$D$14,MATCH(C8,Depreciation!$B$5:$B$14,1)+1)-INDEX(Depreciation!$D$5:$D$14,MATCH(C8,Depreciation!$B$5:$B$14,1))),INDEX(Depreciation!$D$5:$D$14,MATCH(C8,Depreciation!$B$5:$B$14,1))) -> 0.17314286 | I8: =IFERROR(MIN(D8,D8*H8/G8),0) -> 4597.2414 | J8: =D8-I8 -> 6402.7586 | K8: =IFERROR(J8/E8,0) -> 0.058206897 | L8: =MAX(0,MIN(C8,100000)-B8) -> 0 | M8: =MAX(0,MIN(C8,150000)-MAX(B8,100000)) -> 50000 | N8: =MAX(0,C8-MAX(B8,150000)) -> 60000 | O8: =IFERROR((L8*Inputs!$C$23+M8*Inputs!$C$24+N8*Inputs!$C$25)/E8,0) -> 0.081818182 | P8: =IFERROR(Inputs!$C$13/24,0) -> 0.14791667 | Q8: =IFERROR(Inputs!$C$15/Inputs!$C$17,0) -> 0.016363636 | R8: =Inputs!$C$18 -> 0.08 | S8: =IFERROR((Inputs!$C$19+Inputs!$C$20)/Inputs!$C$5,0) -> 0.037272727 | T8: =IFERROR(D8*Inputs!$C$46/E8,0) -> 0.007 | U8: =IFERROR(IF(Inputs!$C$32="Cash",(D8+I8)/2*Inputs!$C$33*F8,(D8*(1-Inputs!$C$35)*Inputs!$C$36*Inputs!$C$34*F8+D8*Inputs!$C$35*Inputs!$C$33*F8))/E8,0) -> 0.0063806897 | V8: =K8+O8+P8+Q8+R8+S8+T8+U8 -> 0.4349588 | W8: =V8*Inputs!$C$5 -> 23922.734
A9: E — Buy new/CPO 5k, run to 200k | B9: 5000 | C9: 200000 | D9: 42000 | E9: =C9-B9 -> 195000 | F9: =IFERROR(E9/Inputs!$C$5,0) -> 3.5454545 | G9: =IFERROR(INDEX(Depreciation!$D$5:$D$14,MATCH(B9,Depreciation!$B$5:$B$14,1))+(B9-INDEX(Depreciation!$B$5:$B$14,MATCH(B9,Depreciation!$B$5:$B$14,1)))/(INDEX(Depreciation!$B$5:$B$14,MATCH(B9,Depreciation!$B$5:$B$14,1)+1)-INDEX(Depreciation!$B$5:$B$14,MATCH(B9,Depreciation!$B$5:$B$14,1)))*(INDEX(Depreciation!$D$5:$D$14,MATCH(B9,Depreciation!$B$5:$B$14,1)+1)-INDEX(Depreciation!$D$5:$D$14,MATCH(B9,Depreciation!$B$5:$B$14,1))),INDEX(Depreciation!$D$5:$D$14,MATCH(B9,Depreciation!$B$5:$B$14,1))) -> 0.98428571 | H9: =IFERROR(INDEX(Depreciation!$D$5:$D$14,MATCH(C9,Depreciation!$B$5:$B$14,1))+(C9-INDEX(Depreciation!$B$5:$B$14,MATCH(C9,Depreciation!$B$5:$B$14,1)))/(INDEX(Depreciation!$B$5:$B$14,MATCH(C9,Depreciation!$B$5:$B$14,1)+1)-INDEX(Depreciation!$B$5:$B$14,MATCH(C9,Depreciation!$B$5:$B$14,1)))*(INDEX(Depreciation!$D$5:$D$14,MATCH(C9,Depreciation!$B$5:$B$14,1)+1)-INDEX(Depreciation!$D$5:$D$14,MATCH(C9,Depreciation!$B$5:$B$14,1))),INDEX(Depreciation!$D$5:$D$14,MATCH(C9,Depreciation!$B$5:$B$14,1))) -> 0.18428571 | I9: =IFERROR(MIN(D9,D9*H9/G9),0) -> 7863.5704 | J9: =D9-I9 -> 34136.43 | K9: =IFERROR(J9/E9,0) -> 0.17505861 | L9: =MAX(0,MIN(C9,100000)-B9) -> 95000 | M9: =MAX(0,MIN(C9,150000)-MAX(B9,100000)) -> 50000 | N9: =MAX(0,C9-MAX(B9,150000)) -> 50000 | O9: =IFERROR((L9*Inputs!$C$23+M9*Inputs!$C$24+N9*Inputs!$C$25)/E9,0) -> 0.055641026 | P9: =IFERROR(Inputs!$C$13/24,0) -> 0.14791667 | Q9: =IFERROR(Inputs!$C$15/Inputs!$C$17,0) -> 0.016363636 | R9: =Inputs!$C$18 -> 0.08 | S9: =IFERROR((Inputs!$C$19+Inputs!$C$20)/Inputs!$C$5,0) -> 0.037272727 | T9: =IFERROR(D9*Inputs!$C$46/E9,0) -> 0.015076923 | U9: =IFERROR(IF(Inputs!$C$32="Cash",(D9+I9)/2*Inputs!$C$33*F9,(D9*(1-Inputs!$C$35)*Inputs!$C$36*Inputs!$C$34*F9+D9*Inputs!$C$35*Inputs!$C$33*F9))/E9,0) -> 0.020398733 | V9: =K9+O9+P9+Q9+R9+S9+T9+U9 -> 0.54772833 | W9: =V9*Inputs!$C$5 -> 30125.058
A10: Assumes a 24 mpg mid-size SUV and crossover tires for all strategies so the comparison isolates buy/sell timing rather than vehicle choice.
A12: LEASE — why it's excluded
A13: Typical lease mileage cap (mi/yr) | C13: 12000
A14: Annual miles driven | C14: =Inputs!$C$5 -> 55000
A15: Overage miles per year | C15: =MAX(0,C14-C13) -> 43000
A16: Overage charge ($/mi, low end) | C16: 0.15
A17: Overage charge ($/mi, high end) | C17: 0.3
A18: Annual overage penalty — low | C18: =C15*C16 -> 6450
A19: Annual overage penalty — high | C19: =C15*C17 -> 12900
A20: Overage alone runs $6,000-$13,500 a year before a single lease payment. Not a close call.
A22: • Depreciation per mile keeps falling as you buy higher on the odometer — Strategy D is less than half of Strategy B. What kills D is repair variance and downtime, which the reserve rates only partly capture. For a driver whose income depends on being somewhere, a tow is a repair bill plus an unbillable day.
A23: • 180,000 is not the depreciation-optimal exit. The curve is flattest past 150k, so pure depreciation math says hold longer. Repair variance is what argues for getting out. On a Toyota with credible 250k legs, stretching toward 200k genuinely does lower cost per mile — you're accepting a wider distribution to get there.
A24: • Strategy E is worst because you personally absorb the first-year cliff (KBB puts it near 20%) that Strategies A-D let someone else eat.
A25: • Two-cheap-vehicles-in-rotation isn't modeled because its economics hinge almost entirely on whether the owner does his own brakes and suspension. If he does, it becomes competitive; if not, doubled failure exposure sinks it.

Sheet HoldPeriod
A1: Hold-Period Resale Analysis
A2: How much the vehicle is worth, and what depreciation costs per mile, at each length of ownership. Driven by the buy odometer and annual miles on the Inputs tab.
A3: At 55,000 mi/yr a 2-year hold means selling at 150,000 miles. A 3-year hold means 205,000.
A5: Model | B5: Category | C5: Tier | D5: Purchase price | E5: Resale mult. | F5: 1yr sell odo | G5: 1yr resale | H5: 1yr deprec $/mi | I5: 2yr sell odo | J5: 2yr resale | K5: 2yr deprec $/mi | L5: 2.5yr sell odo | M5: 2.5yr resale | N5: 2.5yr deprec $/mi | O5: 3yr sell odo | P5: 3yr resale | Q5: 3yr deprec $/mi | R5: 4yr sell odo | S5: 4yr resale | T5: 4yr deprec $/mi
A6: Chevrolet Tahoe | B6: Full-size BOF SUV | C6: T1 | D6: =Models!G7 -> 46000 | E6: =Models!F7 -> 0.93986254 | F6: =Depreciation!$C$32 -> 95000 | G6: =MIN($D6,$D6*Depreciation!$E$32*$E6) -> 22963.417 | H6: =IFERROR(($D6-G6)/(1*Inputs!$C$5),0) -> 0.41884696 | I6: =Depreciation!$C$33 -> 150000 | J6: =MIN($D6,$D6*Depreciation!$E$33*$E6) -> 13271.928 | K6: =IFERROR(($D6-J6)/(2*Inputs!$C$5),0) -> 0.29752793 | L6: =Depreciation!$C$34 -> 177500 | M6: =MIN($D6,$D6*Depreciation!$E$34*$E6) -> 11262.498 | N6: =IFERROR(($D6-M6)/(2.5*Inputs!$C$5),0) -> 0.25263638 | O6: =Depreciation!$C$35 -> 205000 | P6: =MIN($D6,$D6*Depreciation!$E$35*$E6) -> 9327.63 | Q6: =IFERROR(($D6-P6)/(3*Inputs!$C$5),0) -> 0.22225679 | R6: =Depreciation!$C$36 -> 260000 | S6: =MIN($D6,$D6*Depreciation!$E$36*$E6) -> 6710.5252 | T6: =IFERROR(($D6-S6)/(4*Inputs!$C$5),0) -> 0.17858852
A7: Chevrolet Tahoe 3.0L Duramax | B7: Full-size BOF SUV | C7: T1 | D7: =Models!G8 -> 48000 | E7: =Models!F8 -> 0.93986254 | F7: =Depreciation!$C$32 -> 95000 | G7: =MIN($D7,$D7*Depreciation!$E$32*$E7) -> 23961.827 | H7: =IFERROR(($D7-G7)/(1*Inputs!$C$5),0) -> 0.4370577 | I7: =Depreciation!$C$33 -> 150000 | J7: =MIN($D7,$D7*Depreciation!$E$33*$E7) -> 13848.968 | K7: =IFERROR(($D7-J7)/(2*Inputs!$C$5),0) -> 0.31046393 | L7: =Depreciation!$C$34 -> 177500 | M7: =MIN($D7,$D7*Depreciation!$E$34*$E7) -> 11752.172 | N7: =IFERROR(($D7-M7)/(2.5*Inputs!$C$5),0) -> 0.26362057 | O7: =Depreciation!$C$35 -> 205000 | P7: =MIN($D7,$D7*Depreciation!$E$35*$E7) -> 9733.1791 | Q7: =IFERROR(($D7-P7)/(3*Inputs!$C$5),0) -> 0.23192013 | R7: =Depreciation!$C$36 -> 260000 | S7: =MIN($D7,$D7*Depreciation!$E$36*$E7) -> 7002.2872 | T7: =IFERROR(($D7-S7)/(4*Inputs!$C$5),0) -> 0.18635324
A8: Chevrolet Suburban | B8: Full-size BOF SUV | C8: T1 | D8: =Models!G9 -> 45000 | E8: =Models!F9 -> 0.7628866 | F8: =Depreciation!$C$32 -> 95000 | G8: =MIN($D8,$D8*Depreciation!$E$32*$E8) -> 18234.205 | H8: =IFERROR(($D8-G8)/(1*Inputs!$C$5),0) -> 0.48665081 | I8: =Depreciation!$C$33 -> 150000 | J8: =MIN($D8,$D8*Depreciation!$E$33*$E8) -> 10538.634 | K8: =IFERROR(($D8-J8)/(2*Inputs!$C$5),0) -> 0.31328514 | L8: =Depreciation!$C$34 -> 177500 | M8: =MIN($D8,$D8*Depreciation!$E$34*$E8) -> 8943.0376 | N8: =IFERROR(($D8-M8)/(2.5*Inputs!$C$5),0) -> 0.26223245 | O8: =Depreciation!$C$35 -> 205000 | P8: =MIN($D8,$D8*Depreciation!$E$35*$E8) -> 7406.6468 | Q8: =IFERROR(($D8-P8)/(3*Inputs!$C$5),0) -> 0.2278385 | R8: =Depreciation!$C$36 -> 260000 | S8: =MIN($D8,$D8*Depreciation!$E$36*$E8) -> 5328.5229 | T8: =IFERROR(($D8-S8)/(4*Inputs!$C$5),0) -> 0.1803249
A9: GMC Yukon | B9: Full-size BOF SUV | C9: T1 | D9: =Models!G10 -> 49000 | E9: =Models!F10 -> 0.89347079 | F9: =Depreciation!$C$32 -> 95000 | G9: =MIN($D9,$D9*Depreciation!$E$32*$E9) -> 23253.631 | H9: =IFERROR(($D9-G9)/(1*Inputs!$C$5),0) -> 0.46811579 | I9: =Depreciation!$C$33 -> 150000 | J9: =MIN($D9,$D9*Depreciation!$E$33*$E9) -> 13439.66 | K9: =IFERROR(($D9-J9)/(2*Inputs!$C$5),0) -> 0.32327582 | L9: =Depreciation!$C$34 -> 177500 | M9: =MIN($D9,$D9*Depreciation!$E$34*$E9) -> 11404.835 | N9: =IFERROR(($D9-M9)/(2.5*Inputs!$C$5),0) -> 0.27341938 | O9: =Depreciation!$C$35 -> 205000 | P9: =MIN($D9,$D9*Depreciation!$E$35*$E9) -> 9445.5136 | Q9: =IFERROR(($D9-P9)/(3*Inputs!$C$5),0) -> 0.23972416 | R9: =Depreciation!$C$36 -> 260000 | S9: =MIN($D9,$D9*Depreciation!$E$36*$E9) -> 6795.3335 | T9: =IFERROR(($D9-S9)/(4*Inputs!$C$5),0) -> 0.19183939
A10: GMC Yukon XL | B10: Full-size BOF SUV | C10: T1 | D10: =Models!G11 -> 50000 | E10: =Models!F11 -> 0.89347079 | F10: =Depreciation!$C$32 -> 95000 | G10: =MIN($D10,$D10*Depreciation!$E$32*$E10) -> 23728.195 | H10: =IFERROR(($D10-G10)/(1*Inputs!$C$5),0) -> 0.47766918 | I10: =Depreciation!$C$33 -> 150000 | J10: =MIN($D10,$D10*Depreciation!$E$33*$E10) -> 13713.938 | K10: =IFERROR(($D10-J10)/(2*Inputs!$C$5),0) -> 0.32987329 | L10: =Depreciation!$C$34 -> 177500 | M10: =MIN($D10,$D10*Depreciation!$E$34*$E10) -> 11637.586 | N10: =IFERROR(($D10-M10)/(2.5*Inputs!$C$5),0) -> 0.27899937 | O10: =Depreciation!$C$35 -> 205000 | P10: =MIN($D10,$D10*Depreciation!$E$35*$E10) -> 9638.2792 | Q10: =IFERROR(($D10-P10)/(3*Inputs!$C$5),0) -> 0.24461649 | R10: =Depreciation!$C$36 -> 260000 | S10: =MIN($D10,$D10*Depreciation!$E$36*$E10) -> 6934.0138 | T10: =IFERROR(($D10-S10)/(4*Inputs!$C$5),0) -> 0.19575448
A11: Ford Expedition | B11: Full-size BOF SUV | C11: T2 | D11: =Models!G12 -> 43000 | E11: =Models!F12 -> 0.68728522 | F11: =Depreciation!$C$32 -> 95000 | G11: =MIN($D11,$D11*Depreciation!$E$32*$E11) -> 15697.114 | H11: =IFERROR(($D11-G11)/(1*Inputs!$C$5),0) -> 0.49641611 | I11: =Depreciation!$C$33 -> 150000 | J11: =MIN($D11,$D11*Depreciation!$E$33*$E11) -> 9072.2977 | K11: =IFERROR(($D11-J11)/(2*Inputs!$C$5),0) -> 0.30843366 | L11: =Depreciation!$C$34 -> 177500 | M11: =MIN($D11,$D11*Depreciation!$E$34*$E11) -> 7698.7111 | N11: =IFERROR(($D11-M11)/(2.5*Inputs!$C$5),0) -> 0.25673665 | O11: =Depreciation!$C$35 -> 205000 | P11: =MIN($D11,$D11*Depreciation!$E$35*$E11) -> 6376.0924 | Q11: =IFERROR(($D11-P11)/(3*Inputs!$C$5),0) -> 0.22196308 | R11: =Depreciation!$C$36 -> 260000 | S11: =MIN($D11,$D11*Depreciation!$E$36*$E11) -> 4587.1168 | T11: =IFERROR(($D11-S11)/(4*Inputs!$C$5),0) -> 0.17460401
A12: Toyota Sequoia (pre-2023 5.7 V8) | B12: Full-size BOF SUV | C12: T1 | D12: =Models!G13 -> 46000 | E12: =Models!F13 -> 0.99656357 | F12: =Depreciation!$C$32 -> 95000 | G12: =MIN($D12,$D12*Depreciation!$E$32*$E12) -> 24348.779 | H12: =IFERROR(($D12-G12)/(1*Inputs!$C$5),0) -> 0.39365857 | I12: =Depreciation!$C$33 -> 150000 | J12: =MIN($D12,$D12*Depreciation!$E$33*$E12) -> 14072.611 | K12: =IFERROR(($D12-J12)/(2*Inputs!$C$5),0) -> 0.29024899 | L12: =Depreciation!$C$34 -> 177500 | M12: =MIN($D12,$D12*Depreciation!$E$34*$E12) -> 11941.954 | N12: =IFERROR(($D12-M12)/(2.5*Inputs!$C$5),0) -> 0.24769488 | O12: =Depreciation!$C$35 -> 205000 | P12: =MIN($D12,$D12*Depreciation!$E$35*$E12) -> 9890.3572 | Q12: =IFERROR(($D12-P12)/(3*Inputs!$C$5),0) -> 0.21884632 | R12: =Depreciation!$C$36 -> 260000 | S12: =MIN($D12,$D12*Depreciation!$E$36*$E12) -> 7115.3649 | T12: =IFERROR(($D12-S12)/(4*Inputs!$C$5),0) -> 0.17674834
A13: Nissan Armada | B13: Full-size BOF SUV | C13: T2 | D13: =Models!G14 -> 32000 | E13: =Models!F14 -> 0.68728522 | F13: =Depreciation!$C$32 -> 95000 | G13: =MIN($D13,$D13*Depreciation!$E$32*$E13) -> 11681.573 | H13: =IFERROR(($D13-G13)/(1*Inputs!$C$5),0) -> 0.36942595 | I13: =Depreciation!$C$33 -> 150000 | J13: =MIN($D13,$D13*Depreciation!$E$33*$E13) -> 6751.4774 | K13: =IFERROR(($D13-J13)/(2*Inputs!$C$5),0) -> 0.22953202 | L13: =Depreciation!$C$34 -> 177500 | M13: =MIN($D13,$D13*Depreciation!$E$34*$E13) -> 5729.2733 | N13: =IFERROR(($D13-M13)/(2.5*Inputs!$C$5),0) -> 0.19105983 | O13: =Depreciation!$C$35 -> 205000 | P13: =MIN($D13,$D13*Depreciation!$E$35*$E13) -> 4744.999 | Q13: =IFERROR(($D13-P13)/(3*Inputs!$C$5),0) -> 0.16518182 | R13: =Depreciation!$C$36 -> 260000 | S13: =MIN($D13,$D13*Depreciation!$E$36*$E13) -> 3413.6683 | T13: =IFERROR(($D13-S13)/(4*Inputs!$C$5),0) -> 0.12993787
A14: Cadillac Escalade | B14: Full-size BOF SUV | C14: T3 | D14: =Models!G15 -> 70000 | E14: =Models!F15 -> 0.65635739 | F14: =Depreciation!$C$32 -> 95000 | G14: =MIN($D14,$D14*Depreciation!$E$32*$E14) -> 24403.536 | H14: =IFERROR(($D14-G14)/(1*Inputs!$C$5),0) -> 0.82902662 | I14: =Depreciation!$C$33 -> 150000 | J14: =MIN($D14,$D14*Depreciation!$E$33*$E14) -> 14104.258 | K14: =IFERROR(($D14-J14)/(2*Inputs!$C$5),0) -> 0.50814311 | L14: =Depreciation!$C$34 -> 177500 | M14: =MIN($D14,$D14*Depreciation!$E$34*$E14) -> 11968.81 | N14: =IFERROR(($D14-M14)/(2.5*Inputs!$C$5),0) -> 0.42204502 | O14: =Depreciation!$C$35 -> 205000 | P14: =MIN($D14,$D14*Depreciation!$E$35*$E14) -> 9912.5994 | Q14: =IFERROR(($D14-P14)/(3*Inputs!$C$5),0) -> 0.36416606 | R14: =Depreciation!$C$36 -> 260000 | S14: =MIN($D14,$D14*Depreciation!$E$36*$E14) -> 7131.3665 | T14: =IFERROR(($D14-S14)/(4*Inputs!$C$5),0) -> 0.28576652
A15: Jeep Grand Wagoneer | B15: Full-size BOF SUV | C15: T3 | D15: =Models!G16 -> 54000 | E15: =Models!F16 -> 0.75601375 | F15: =Depreciation!$C$32 -> 95000 | G15: =MIN($D15,$D15*Depreciation!$E$32*$E15) -> 21683.92 | H15: =IFERROR(($D15-G15)/(1*Inputs!$C$5),0) -> 0.58756509 | I15: =Depreciation!$C$33 -> 150000 | J15: =MIN($D15,$D15*Depreciation!$E$33*$E15) -> 12532.43 | K15: =IFERROR(($D15-J15)/(2*Inputs!$C$5),0) -> 0.37697791 | L15: =Depreciation!$C$34 -> 177500 | M15: =MIN($D15,$D15*Depreciation!$E$34*$E15) -> 10634.964 | N15: =IFERROR(($D15-M15)/(2.5*Inputs!$C$5),0) -> 0.31538208 | O15: =Depreciation!$C$35 -> 205000 | P15: =MIN($D15,$D15*Depreciation!$E$35*$E15) -> 8807.9043 | Q15: =IFERROR(($D15-P15)/(3*Inputs!$C$5),0) -> 0.27389149 | R15: =Depreciation!$C$36 -> 260000 | S15: =MIN($D15,$D15*Depreciation!$E$36*$E15) -> 6336.6218 | T15: =IFERROR(($D15-S15)/(4*Inputs!$C$5),0) -> 0.21665172
A16: Jeep Grand Cherokee | B16: Mid-size SUV | C16: T2 | D16: =Models!G17 -> 32000 | E16: =Models!F17 -> 0.8419244 | F16: =Depreciation!$C$32 -> 95000 | G16: =MIN($D16,$D16*Depreciation!$E$32*$E16) -> 14309.927 | H16: =IFERROR(($D16-G16)/(1*Inputs!$C$5),0) -> 0.32163769 | I16: =Depreciation!$C$33 -> 150000 | J16: =MIN($D16,$D16*Depreciation!$E$33*$E16) -> 8270.5598 | K16: =IFERROR(($D16-J16)/(2*Inputs!$C$5),0) -> 0.21572218 | L16: =Depreciation!$C$34 -> 177500 | M16: =MIN($D16,$D16*Depreciation!$E$34*$E16) -> 7018.3598 | N16: =IFERROR(($D16-M16)/(2.5*Inputs!$C$5),0) -> 0.18168466 | O16: =Depreciation!$C$35 -> 205000 | P16: =MIN($D16,$D16*Depreciation!$E$35*$E16) -> 5812.6237 | Q16: =IFERROR(($D16-P16)/(3*Inputs!$C$5),0) -> 0.15871137 | R16: =Depreciation!$C$36 -> 260000 | S16: =MIN($D16,$D16*Depreciation!$E$36*$E16) -> 4181.7437 | T16: =IFERROR(($D16-S16)/(4*Inputs!$C$5),0) -> 0.12644662
